[2024-06-29T20:44:21.607+0000] {local_task_job_runner.py:120} INFO - ::group::Pre task execution logs
[2024-06-29T20:44:21.633+0000] {taskinstance.py:2076} INFO - Dependencies all met for dep_context=non-requeueable deps ti=<TaskInstance: northwindDWH.data_delivery manual__2024-06-29T20:44:16.467964+00:00 [queued]>
[2024-06-29T20:44:21.641+0000] {taskinstance.py:2076} INFO - Dependencies all met for dep_context=requeueable deps ti=<TaskInstance: northwindDWH.data_delivery manual__2024-06-29T20:44:16.467964+00:00 [queued]>
[2024-06-29T20:44:21.641+0000] {taskinstance.py:2306} INFO - Starting attempt 1 of 1
[2024-06-29T20:44:21.655+0000] {taskinstance.py:2330} INFO - Executing <Task(PythonOperator): data_delivery> on 2024-06-29 20:44:16.467964+00:00
[2024-06-29T20:44:21.664+0000] {warnings.py:110} WARNING - /home/***/.local/lib/python3.12/site-packages/***/task/task_runner/standard_task_runner.py:61: DeprecationWarning: This process (pid=77) is multi-threaded, use of fork() may lead to deadlocks in the child.
  pid = os.fork()

[2024-06-29T20:44:21.665+0000] {standard_task_runner.py:63} INFO - Started process 79 to run task
[2024-06-29T20:44:21.666+0000] {standard_task_runner.py:90} INFO - Running: ['***', 'tasks', 'run', 'northwindDWH', 'data_delivery', 'manual__2024-06-29T20:44:16.467964+00:00', '--job-id', '11', '--raw', '--subdir', 'DAGS_FOLDER/northwindDWH.py', '--cfg-path', '/tmp/tmpe5jjui5m']
[2024-06-29T20:44:21.668+0000] {standard_task_runner.py:91} INFO - Job 11: Subtask data_delivery
[2024-06-29T20:44:21.680+0000] {warnings.py:110} WARNING - /home/***/.local/lib/python3.12/site-packages/***/settings.py:195: DeprecationWarning: The sql_alchemy_conn option in [core] has been moved to the sql_alchemy_conn option in [database] - the old setting has been used, but please update your config.
  SQL_ALCHEMY_CONN = conf.get("database", "SQL_ALCHEMY_CONN")

[2024-06-29T20:44:21.710+0000] {task_command.py:426} INFO - Running <TaskInstance: northwindDWH.data_delivery manual__2024-06-29T20:44:16.467964+00:00 [running]> on host 3abb3aef8f21
[2024-06-29T20:44:21.800+0000] {taskinstance.py:2648} INFO - Exporting env vars: AIRFLOW_CTX_DAG_OWNER='Mahmoud' AIRFLOW_CTX_DAG_ID='northwindDWH' AIRFLOW_CTX_TASK_ID='data_delivery' AIRFLOW_CTX_EXECUTION_DATE='2024-06-29T20:44:16.467964+00:00' AIRFLOW_CTX_TRY_NUMBER='1' AIRFLOW_CTX_DAG_RUN_ID='manual__2024-06-29T20:44:16.467964+00:00'
[2024-06-29T20:44:21.801+0000] {taskinstance.py:430} INFO - ::endgroup::
[2024-06-29T20:44:21.813+0000] {northwindDWH.py:65} INFO - Data delivery started
[2024-06-29T20:44:21.814+0000] {Load_data.py:84} INFO - loading dimEmployee to db ...
[2024-06-29T20:44:21.814+0000] {Transform_data.py:48} INFO - start Extracting dim employee
[2024-06-29T20:44:21.817+0000] {db_utils.py:21} INFO - Connected to PostgreSQL database successfully
[2024-06-29T20:44:21.821+0000] {Transform_data.py:57} INFO - Extract dim employees done
[2024-06-29T20:44:21.821+0000] {db_utils.py:30} INFO - PostgreSQL connection is closed
[2024-06-29T20:44:21.824+0000] {db_utils.py:24} ERROR - Error while connecting to PostgreSQL: connection to server at "172.19.0.2", port 5432 failed: FATAL:  database "northwind_DWH" does not exist

[2024-06-29T20:44:21.825+0000] {Load_data.py:152} INFO - Error while loading dimCustomers: Connection to database failed
[2024-06-29T20:44:21.825+0000] {Load_data.py:156} INFO - loading dimproduct to db ...
[2024-06-29T20:44:21.825+0000] {Transform_data.py:25} INFO - start Extracting dim product
[2024-06-29T20:44:21.829+0000] {db_utils.py:21} INFO - Connected to PostgreSQL database successfully
[2024-06-29T20:44:21.832+0000] {Transform_data.py:39} INFO - Extract dim products done
[2024-06-29T20:44:21.832+0000] {db_utils.py:30} INFO - PostgreSQL connection is closed
[2024-06-29T20:44:21.835+0000] {db_utils.py:24} ERROR - Error while connecting to PostgreSQL: connection to server at "172.19.0.2", port 5432 failed: FATAL:  database "northwind_DWH" does not exist

[2024-06-29T20:44:21.835+0000] {Load_data.py:199} INFO - Error while loading dimCustomers: Connection to database failed
[2024-06-29T20:44:21.835+0000] {Load_data.py:12} INFO - loading dimCustomers to db ...
[2024-06-29T20:44:21.835+0000] {Transform_data.py:7} INFO - start Extracting dim customers
[2024-06-29T20:44:21.838+0000] {db_utils.py:21} INFO - Connected to PostgreSQL database successfully
[2024-06-29T20:44:21.840+0000] {Transform_data.py:16} INFO - Extract dim customer done
[2024-06-29T20:44:21.841+0000] {db_utils.py:30} INFO - PostgreSQL connection is closed
[2024-06-29T20:44:21.844+0000] {db_utils.py:24} ERROR - Error while connecting to PostgreSQL: connection to server at "172.19.0.2", port 5432 failed: FATAL:  database "northwind_DWH" does not exist

[2024-06-29T20:44:21.845+0000] {Load_data.py:80} INFO - Error while loading dimCustomers: Connection to database failed
[2024-06-29T20:44:21.846+0000] {Load_data.py:203} INFO - loading factsales to db ...
[2024-06-29T20:44:21.846+0000] {Transform_data.py:67} INFO - start Extracting fact sales
[2024-06-29T20:44:21.849+0000] {db_utils.py:21} INFO - Connected to PostgreSQL database successfully
[2024-06-29T20:44:21.854+0000] {Transform_data.py:80} INFO - Extract fact sales done
[2024-06-29T20:44:21.854+0000] {db_utils.py:30} INFO - PostgreSQL connection is closed
[2024-06-29T20:44:21.855+0000] {Tables_creations.py:27} INFO - Loading data into table Fact_Sales...
[2024-06-29T20:44:21.857+0000] {db_utils.py:21} INFO - Connected to PostgreSQL database successfully
[2024-06-29T20:44:21.860+0000] {Load_data.py:211} INFO - Error while loading Fact_Sales: duplicate key value violates unique constraint "fact_sales_pkey"
DETAIL:  Key (order_id)=(30) already exists.

[2024-06-29T20:44:21.861+0000] {northwindDWH.py:70} INFO - Data delivery done
[2024-06-29T20:44:21.861+0000] {python.py:237} INFO - Done. Returned value was: None
[2024-06-29T20:44:21.862+0000] {taskinstance.py:441} INFO - ::group::Post task execution logs
[2024-06-29T20:44:21.870+0000] {taskinstance.py:1206} INFO - Marking task as SUCCESS. dag_id=northwindDWH, task_id=data_delivery, run_id=manual__2024-06-29T20:44:16.467964+00:00, execution_date=20240629T204416, start_date=20240629T204421, end_date=20240629T204421
[2024-06-29T20:44:21.919+0000] {local_task_job_runner.py:240} INFO - Task exited with return code 0
[2024-06-29T20:44:21.937+0000] {taskinstance.py:3498} INFO - 0 downstream tasks scheduled from follow-on schedule check
[2024-06-29T20:44:21.939+0000] {local_task_job_runner.py:222} INFO - ::endgroup::
