[2024-06-29T20:36:56.427+0000] {local_task_job_runner.py:120} INFO - ::group::Pre task execution logs
[2024-06-29T20:36:56.447+0000] {taskinstance.py:2076} INFO - Dependencies all met for dep_context=non-requeueable deps ti=<TaskInstance: northwindDWH.data_delivery manual__2024-06-29T20:36:50.581639+00:00 [queued]>
[2024-06-29T20:36:56.456+0000] {taskinstance.py:2076} INFO - Dependencies all met for dep_context=requeueable deps ti=<TaskInstance: northwindDWH.data_delivery manual__2024-06-29T20:36:50.581639+00:00 [queued]>
[2024-06-29T20:36:56.456+0000] {taskinstance.py:2306} INFO - Starting attempt 1 of 1
[2024-06-29T20:36:56.467+0000] {taskinstance.py:2330} INFO - Executing <Task(PythonOperator): data_delivery> on 2024-06-29 20:36:50.581639+00:00
[2024-06-29T20:36:56.476+0000] {warnings.py:110} WARNING - /home/***/.local/lib/python3.12/site-packages/***/task/task_runner/standard_task_runner.py:61: DeprecationWarning: This process (pid=68) is multi-threaded, use of fork() may lead to deadlocks in the child.
  pid = os.fork()

[2024-06-29T20:36:56.477+0000] {standard_task_runner.py:63} INFO - Started process 70 to run task
[2024-06-29T20:36:56.477+0000] {standard_task_runner.py:90} INFO - Running: ['***', 'tasks', 'run', 'northwindDWH', 'data_delivery', 'manual__2024-06-29T20:36:50.581639+00:00', '--job-id', '8', '--raw', '--subdir', 'DAGS_FOLDER/northwindDWH.py', '--cfg-path', '/tmp/tmpv4tdel_k']
[2024-06-29T20:36:56.479+0000] {standard_task_runner.py:91} INFO - Job 8: Subtask data_delivery
[2024-06-29T20:36:56.490+0000] {warnings.py:110} WARNING - /home/***/.local/lib/python3.12/site-packages/***/settings.py:195: DeprecationWarning: The sql_alchemy_conn option in [core] has been moved to the sql_alchemy_conn option in [database] - the old setting has been used, but please update your config.
  SQL_ALCHEMY_CONN = conf.get("database", "SQL_ALCHEMY_CONN")

[2024-06-29T20:36:56.517+0000] {task_command.py:426} INFO - Running <TaskInstance: northwindDWH.data_delivery manual__2024-06-29T20:36:50.581639+00:00 [running]> on host 3abb3aef8f21
[2024-06-29T20:36:56.615+0000] {taskinstance.py:2648} INFO - Exporting env vars: AIRFLOW_CTX_DAG_OWNER='Mahmoud' AIRFLOW_CTX_DAG_ID='northwindDWH' AIRFLOW_CTX_TASK_ID='data_delivery' AIRFLOW_CTX_EXECUTION_DATE='2024-06-29T20:36:50.581639+00:00' AIRFLOW_CTX_TRY_NUMBER='1' AIRFLOW_CTX_DAG_RUN_ID='manual__2024-06-29T20:36:50.581639+00:00'
[2024-06-29T20:36:56.617+0000] {taskinstance.py:430} INFO - ::endgroup::
[2024-06-29T20:36:56.632+0000] {northwindDWH.py:65} INFO - Data delivery started
[2024-06-29T20:36:56.633+0000] {Load_data.py:84} INFO - loading dimEmployee to db ...
[2024-06-29T20:36:56.633+0000] {Transform_data.py:48} INFO - start Extracting dim employee
[2024-06-29T20:36:56.636+0000] {db_utils.py:21} INFO - Connected to PostgreSQL database successfully
[2024-06-29T20:36:56.641+0000] {Transform_data.py:57} INFO - Extract dim employees done
[2024-06-29T20:36:56.641+0000] {db_utils.py:30} INFO - PostgreSQL connection is closed
[2024-06-29T20:36:56.647+0000] {db_utils.py:24} ERROR - Error while connecting to PostgreSQL: connection to server at "172.19.0.2", port 5432 failed: FATAL:  database "northwind_DWH" does not exist

[2024-06-29T20:36:56.648+0000] {Load_data.py:152} INFO - Error while loading dimCustomers: Connection to database failed
[2024-06-29T20:36:56.648+0000] {Load_data.py:156} INFO - loading dimproduct to db ...
[2024-06-29T20:36:56.648+0000] {Transform_data.py:25} INFO - start Extracting dim product
[2024-06-29T20:36:56.652+0000] {db_utils.py:21} INFO - Connected to PostgreSQL database successfully
[2024-06-29T20:36:56.656+0000] {Transform_data.py:39} INFO - Extract dim products done
[2024-06-29T20:36:56.657+0000] {db_utils.py:30} INFO - PostgreSQL connection is closed
[2024-06-29T20:36:56.660+0000] {db_utils.py:24} ERROR - Error while connecting to PostgreSQL: connection to server at "172.19.0.2", port 5432 failed: FATAL:  database "northwind_DWH" does not exist

[2024-06-29T20:36:56.661+0000] {Load_data.py:199} INFO - Error while loading dimCustomers: Connection to database failed
[2024-06-29T20:36:56.662+0000] {Load_data.py:12} INFO - loading dimCustomers to db ...
[2024-06-29T20:36:56.663+0000] {Transform_data.py:7} INFO - start Extracting dim customers
[2024-06-29T20:36:56.666+0000] {db_utils.py:21} INFO - Connected to PostgreSQL database successfully
[2024-06-29T20:36:56.668+0000] {Transform_data.py:16} INFO - Extract dim customer done
[2024-06-29T20:36:56.668+0000] {db_utils.py:30} INFO - PostgreSQL connection is closed
[2024-06-29T20:36:56.672+0000] {db_utils.py:24} ERROR - Error while connecting to PostgreSQL: connection to server at "172.19.0.2", port 5432 failed: FATAL:  database "northwind_DWH" does not exist

[2024-06-29T20:36:56.673+0000] {Load_data.py:80} INFO - Error while loading dimCustomers: Connection to database failed
[2024-06-29T20:36:56.673+0000] {Load_data.py:203} INFO - loading factsales to db ...
[2024-06-29T20:36:56.674+0000] {Transform_data.py:67} INFO - start Extracting fact sales
[2024-06-29T20:36:56.677+0000] {db_utils.py:21} INFO - Connected to PostgreSQL database successfully
[2024-06-29T20:36:56.682+0000] {Transform_data.py:80} INFO - Extract fact sales done
[2024-06-29T20:36:56.682+0000] {db_utils.py:30} INFO - PostgreSQL connection is closed
[2024-06-29T20:36:56.682+0000] {Tables_creations.py:27} INFO - Loading data into table Fact_Sales...
[2024-06-29T20:36:56.686+0000] {db_utils.py:21} INFO - Connected to PostgreSQL database successfully
[2024-06-29T20:36:56.688+0000] {Load_data.py:211} INFO - Error while loading Fact_Sales: relation "fact_sales" does not exist
LINE 1: INSERT INTO Fact_Sales (order_id, product_id, employee_id, c...
                    ^

[2024-06-29T20:36:56.689+0000] {northwindDWH.py:70} INFO - Data delivery done
[2024-06-29T20:36:56.689+0000] {python.py:237} INFO - Done. Returned value was: None
[2024-06-29T20:36:56.690+0000] {taskinstance.py:441} INFO - ::group::Post task execution logs
[2024-06-29T20:36:56.699+0000] {taskinstance.py:1206} INFO - Marking task as SUCCESS. dag_id=northwindDWH, task_id=data_delivery, run_id=manual__2024-06-29T20:36:50.581639+00:00, execution_date=20240629T203650, start_date=20240629T203656, end_date=20240629T203656
[2024-06-29T20:36:56.730+0000] {local_task_job_runner.py:240} INFO - Task exited with return code 0
[2024-06-29T20:36:56.749+0000] {taskinstance.py:3498} INFO - 0 downstream tasks scheduled from follow-on schedule check
[2024-06-29T20:36:56.751+0000] {local_task_job_runner.py:222} INFO - ::endgroup::
